<?xml version="1.0" ?>
<robot name="barq" xmlns:xacro="http://www.ros.org/wiki/xacro">

  <material name="dark_grey">  <color rgba="0.20 0.20 0.20 1.0"/> </material>
  <material name="light_grey"> <color rgba="0.65 0.65 0.65 1.0"/> </material>

  <!-- BASE LINK -->
  <link name="base_link">
    <visual>
      <origin rpy="0 0 -1.5708" xyz="0 0 0"/>
      <geometry><mesh filename="package://barq_description/meshes/base_link.dae" scale="1 1 1"/></geometry>
      <material name="light_grey"/>
    </visual>
    <collision>
      <origin rpy="0 0 0" xyz="0 0 0"/>
      <geometry><box size="0.258 0.117 0.085"/></geometry>
    </collision>
    <!-- Measured 2026-06-11 (Aryaman): incl. electronics/fasteners. Inertia: solid box
         0.258 x 0.117 x 0.085 at the measured mass. -->
    <inertial>
      <mass value="1.42"/>
      <origin rpy="0 0 0" xyz="0 0 0"/>
      <inertia ixx="2.47e-3" ixy="0" ixz="0" iyy="8.73e-3" iyz="0" izz="9.50e-3"/>
    </inertial>
  </link>

  <!-- ═══════════════ LIDAR (STL-27L-class 2D, Q-015: purchase deferred, sim-first) ═══════════
       Aft-of-center deck mount (nose reserved for a future depth camera). Pitched -4.5 deg to
       counter the nose-down stance trim (D-016) so the scan plane is level at nominal stance.
       Mass modelled so dynamics/RL train on the robot that will exist. -->
  <link name="laser">
    <visual>
      <origin rpy="0 0 0" xyz="0 0 0"/>
      <geometry><cylinder radius="0.019" length="0.035"/></geometry>
      <material name="dark_grey"/>
    </visual>
    <inertial>
      <mass value="0.047"/>
      <origin rpy="0 0 0" xyz="0 0 0"/>
      <inertia ixx="1.0e-5" ixy="0" ixz="0" iyy="1.0e-5" iyz="0" izz="8.5e-6"/>
    </inertial>
  </link>
  <joint name="laser_joint" type="fixed">
    <parent link="base_link"/>    <child link="laser"/>
    <origin rpy="0 -0.0785 0" xyz="-0.04 0 0.066"/>
  </joint>

  <!-- ═══════════════ FL LEG ═══════════════ -->
  <joint name="FL_hip_joint" type="revolute">
    <parent link="base_link"/>    <child link="FL_coxa_link"/>
    <origin rpy="0 0 0" xyz="0.108484 0.0171913 0.00022012"/>
    <axis xyz="1 0 0"/>
    <limit effort="2.94" lower="-0.785" upper="0.785" velocity="5.24"/>
    <dynamics damping="0.05" friction="0.0"/>
  </joint>
  <link name="FL_coxa_link">
    <visual>
      <origin rpy="3.14159265358979 0 -1.5708" xyz="0 0 0"/>
      <geometry><mesh filename="package://barq_description/meshes/coxa.dae" scale="1 1 1"/></geometry>
      <material name="dark_grey"/>
    </visual>
    <inertial>
      <mass value="0.0733"/>
      <origin rpy="0 0 0" xyz="0.00872 0.0215346 0"/>
      <inertia ixx="3.2e-5" ixy="0" ixz="0" iyy="2.0e-5" iyz="0" izz="3.2e-5"/>
    </inertial>
  </link>

  <joint name="FL_knee_joint" type="revolute">
    <parent link="FL_coxa_link"/>    <child link="FL_femur_link"/>
    <origin rpy="0 0 0" xyz="0.01744 0.0430692 0"/>
    <axis xyz="0 1 0"/>
    <limit effort="2.94" lower="-1.57" upper="1.57" velocity="5.24"/>
    <dynamics damping="0.05" friction="0.0"/>
  </joint>
  <link name="FL_femur_link">
    <visual>
      <origin rpy="0 0 -1.5708" xyz="0 0 0"/>
      <geometry><mesh filename="package://barq_description/meshes/mid.dae" scale="1 1 1"/></geometry>
      <material name="dark_grey"/>
    </visual>
    <inertial>
      <mass value="0.1536"/>
      <origin rpy="0 0 0" xyz="0.009472 0.01769995 -0.04999995"/>
      <inertia ixx="1.7e-4" ixy="0" ixz="0" iyy="1.6e-4" iyz="0" izz="5.3e-5"/>
    </inertial>
  </link>

  <joint name="FL_ankle_joint" type="revolute">
    <parent link="FL_femur_link"/>    <child link="FL_tibia_link"/>
    <origin rpy="0 0 0" xyz="0.018944 0.03239997 -0.0999999"/>
    <axis xyz="0 1 0"/>
    <limit effort="2.94" lower="-2.2" upper="1.57" velocity="5.24"/>
    <dynamics damping="0.05" friction="0.0"/>
  </joint>
  <link name="FL_tibia_link">
    <visual>
      <origin rpy="0 0 -1.5708" xyz="0 0 0"/>
      <geometry><mesh filename="package://barq_description/meshes/foot.dae" scale="1 1 1"/></geometry>
      <material name="dark_grey"/>
    </visual>
    <!-- Contact sphere at the kinematic foot point (mesh collisions are unstable/slow in sim) -->
    <collision>
      <origin rpy="0 0 0" xyz="0 0 -0.1"/>
      <geometry><sphere radius="0.012"/></geometry>
    </collision>
    <inertial>
      <mass value="0.030"/>
      <origin rpy="0 0 0" xyz="0 0 -0.04999995"/>
      <inertia ixx="3.3e-5" ixy="0" ixz="0" iyy="3.1e-5" iyz="0" izz="3.3e-6"/>
    </inertial>
  </link>

  <!-- ═══════════════ RL LEG ═══════════════ -->
  <joint name="RL_hip_joint" type="revolute">
    <parent link="base_link"/>    <child link="RL_coxa_link"/>
    <origin rpy="0 0 0" xyz="-0.108371 0.0167905 0.00022176"/>
    <axis xyz="1 0 0"/>
    <limit effort="2.94" lower="-0.785" upper="0.785" velocity="5.24"/>
    <dynamics damping="0.05" friction="0.0"/>
  </joint>
  <link name="RL_coxa_link">
    <visual>
      <origin rpy="0 0 -1.5708" xyz="0 0 0"/>
      <geometry><mesh filename="package://barq_description/meshes/coxa.dae" scale="1 1 1"/></geometry>
      <material name="dark_grey"/>
    </visual>
    <inertial>
      <mass value="0.0733"/>
      <origin rpy="0 0 0" xyz="-0.00872 0.0215346 0"/>
      <inertia ixx="3.2e-5" ixy="0" ixz="0" iyy="2.0e-5" iyz="0" izz="3.2e-5"/>
    </inertial>
  </link>

  <joint name="RL_knee_joint" type="revolute">
    <parent link="RL_coxa_link"/>    <child link="RL_femur_link"/>
    <origin rpy="0 0 0" xyz="-0.01744 0.0430692 0"/>
    <axis xyz="0 1 0"/>
    <limit effort="2.94" lower="-1.57" upper="1.57" velocity="5.24"/>
    <dynamics damping="0.05" friction="0.0"/>
  </joint>
  <link name="RL_femur_link">
    <visual>
      <origin rpy="0 0 -1.5708" xyz="0 0 0"/>
      <geometry><mesh filename="package://barq_description/meshes/mid.dae" scale="1 1 1"/></geometry>
      <material name="dark_grey"/>
    </visual>
    <inertial>
      <mass value="0.1536"/>
      <origin rpy="0 0 0" xyz="0.009472 0.01769995 -0.04999995"/>
      <inertia ixx="1.7e-4" ixy="0" ixz="0" iyy="1.6e-4" iyz="0" izz="5.3e-5"/>
    </inertial>
  </link>

  <joint name="RL_ankle_joint" type="revolute">
    <parent link="RL_femur_link"/>    <child link="RL_tibia_link"/>
    <origin rpy="0 0 0" xyz="0.018944 0.03239997 -0.0999999"/>
    <axis xyz="0 1 0"/>
    <limit effort="2.94" lower="-2.2" upper="1.57" velocity="5.24"/>
    <dynamics damping="0.05" friction="0.0"/>
  </joint>
  <link name="RL_tibia_link">
    <visual>
      <origin rpy="0 0 -1.5708" xyz="0 0 0"/>
      <geometry><mesh filename="package://barq_description/meshes/foot.dae" scale="1 1 1"/></geometry>
      <material name="dark_grey"/>
    </visual>
    <!-- Contact sphere at the kinematic foot point (mesh collisions are unstable/slow in sim) -->
    <collision>
      <origin rpy="0 0 0" xyz="0 0 -0.1"/>
      <geometry><sphere radius="0.012"/></geometry>
    </collision>
    <inertial>
      <mass value="0.030"/>
      <origin rpy="0 0 0" xyz="0 0 -0.04999995"/>
      <inertia ixx="3.3e-5" ixy="0" ixz="0" iyy="3.1e-5" iyz="0" izz="3.3e-6"/>
    </inertial>
  </link>

  <!-- ═══════════════ FR LEG ═══════════════ -->
  <joint name="FR_hip_joint" type="revolute">
    <parent link="base_link"/>    <child link="FR_coxa_link"/>
    <origin rpy="0 0 0" xyz="0.108484 -0.0148092 0.00022176"/>
    <axis xyz="1 0 0"/>
    <limit effort="2.94" lower="-0.785" upper="0.785" velocity="5.24"/>
    <dynamics damping="0.05" friction="0.0"/>
  </joint>
  <link name="FR_coxa_link">
    <visual>
      <origin rpy="0 0 1.5708" xyz="0 0 0"/>
      <geometry><mesh filename="package://barq_description/meshes/coxa.dae" scale="1 1 1"/></geometry>
      <material name="dark_grey"/>
    </visual>
    <inertial>
      <mass value="0.0733"/>
      <origin rpy="0 0 0" xyz="0.00872 -0.0215346 0"/>
      <inertia ixx="3.2e-5" ixy="0" ixz="0" iyy="2.0e-5" iyz="0" izz="3.2e-5"/>
    </inertial>
  </link>

  <joint name="FR_knee_joint" type="revolute">
    <parent link="FR_coxa_link"/>    <child link="FR_femur_link"/>
    <origin rpy="0 0 0" xyz="0.01744 -0.0430692 0"/>
    <axis xyz="0 1 0"/>
    <limit effort="2.94" lower="-1.57" upper="1.57" velocity="5.24"/>
    <dynamics damping="0.05" friction="0.0"/>
  </joint>
  <link name="FR_femur_link">
    <visual>
      <origin rpy="0 0 -1.5708" xyz="0 0 0"/>
      <geometry><mesh filename="package://barq_description/meshes/mid_rev.dae" scale="1 1 1"/></geometry>
      <material name="dark_grey"/>
    </visual>
    <inertial>
      <mass value="0.1536"/>
      <origin rpy="0 0 0" xyz="0.00947205 -0.01769995 -0.04999995"/>
      <inertia ixx="1.7e-4" ixy="0" ixz="0" iyy="1.6e-4" iyz="0" izz="5.3e-5"/>
    </inertial>
  </link>

  <joint name="FR_ankle_joint" type="revolute">
    <parent link="FR_femur_link"/>    <child link="FR_tibia_link"/>
    <origin rpy="0 0 0" xyz="0.0189441 -0.03239997 -0.0999999"/>
    <axis xyz="0 1 0"/>
    <limit effort="2.94" lower="-2.2" upper="1.57" velocity="5.24"/>
    <dynamics damping="0.05" friction="0.0"/>
  </joint>
  <link name="FR_tibia_link">
    <visual>
      <origin rpy="0 0 -1.5708" xyz="0 0 0"/>
      <geometry><mesh filename="package://barq_description/meshes/foot_rev.dae" scale="1 1 1"/></geometry>
      <material name="dark_grey"/>
    </visual>
    <!-- Contact sphere at the kinematic foot point (mesh collisions are unstable/slow in sim) -->
    <collision>
      <origin rpy="0 0 0" xyz="0 0 -0.1"/>
      <geometry><sphere radius="0.012"/></geometry>
    </collision>
    <inertial>
      <mass value="0.030"/>
      <origin rpy="0 0 0" xyz="0 0 -0.04999995"/>
      <inertia ixx="3.3e-5" ixy="0" ixz="0" iyy="3.1e-5" iyz="0" izz="3.3e-6"/>
    </inertial>
  </link>

  <!-- ═══════════════ RR LEG ═══════════════ -->
  <joint name="RR_hip_joint" type="revolute">
    <parent link="base_link"/>    <child link="RR_coxa_link"/>
    <origin rpy="0 0 0" xyz="-0.108371 -0.01521 0.00022012"/>
    <axis xyz="1 0 0"/>
    <limit effort="2.94" lower="-0.785" upper="0.785" velocity="5.24"/>
    <dynamics damping="0.05" friction="0.0"/>
  </joint>
  <link name="RR_coxa_link">
    <visual>
      <origin rpy="3.14159265358979 0 1.5708" xyz="0 0 0"/>
      <geometry><mesh filename="package://barq_description/meshes/coxa.dae" scale="1 1 1"/></geometry>
      <material name="dark_grey"/>
    </visual>
    <inertial>
      <mass value="0.0733"/>
      <origin rpy="0 0 0" xyz="-0.00872 -0.0215346 0"/>
      <inertia ixx="3.2e-5" ixy="0" ixz="0" iyy="2.0e-5" iyz="0" izz="3.2e-5"/>
    </inertial>
  </link>

  <joint name="RR_knee_joint" type="revolute">
    <parent link="RR_coxa_link"/>    <child link="RR_femur_link"/>
    <origin rpy="0 0 0" xyz="-0.01744 -0.0430692 0"/>
    <axis xyz="0 1 0"/>
    <limit effort="2.94" lower="-1.57" upper="1.57" velocity="5.24"/>
    <dynamics damping="0.05" friction="0.0"/>
  </joint>
  <link name="RR_femur_link">
    <visual>
      <origin rpy="0 0 -1.5708" xyz="0 0 0"/>
      <geometry><mesh filename="package://barq_description/meshes/mid_rev.dae" scale="1 1 1"/></geometry>
      <material name="dark_grey"/>
    </visual>
    <inertial>
      <mass value="0.1536"/>
      <origin rpy="0 0 0" xyz="0.00947205 -0.01769995 -0.04999995"/>
      <inertia ixx="1.7e-4" ixy="0" ixz="0" iyy="1.6e-4" iyz="0" izz="5.3e-5"/>
    </inertial>
  </link>

  <joint name="RR_ankle_joint" type="revolute">
    <parent link="RR_femur_link"/>    <child link="RR_tibia_link"/>
    <origin rpy="0 0 0" xyz="0.0189441 -0.03239997 -0.0999999"/>
    <axis xyz="0 1 0"/>
    <limit effort="2.94" lower="-2.2" upper="1.57" velocity="5.24"/>
    <dynamics damping="0.05" friction="0.0"/>
  </joint>
  <link name="RR_tibia_link">
    <visual>
      <origin rpy="0 0 -1.5708" xyz="0 0 0"/>
      <geometry><mesh filename="package://barq_description/meshes/foot_rev.dae" scale="1 1 1"/></geometry>
      <material name="dark_grey"/>
    </visual>
    <!-- Contact sphere at the kinematic foot point (mesh collisions are unstable/slow in sim) -->
    <collision>
      <origin rpy="0 0 0" xyz="0 0 -0.1"/>
      <geometry><sphere radius="0.012"/></geometry>
    </collision>
    <inertial>
      <mass value="0.030"/>
      <origin rpy="0 0 0" xyz="0 0 -0.04999995"/>
      <inertia ixx="3.3e-5" ixy="0" ixz="0" iyy="3.1e-5" iyz="0" izz="3.3e-6"/>
    </inertial>
  </link>

  <!-- ═══════════════ ros2_control (Stage 2B) ═══════════════ -->
  <!-- mode: mock (now) | gazebo (2E) | real (Stage 4). Only the <hardware> plugin changes. -->
  <xacro:arg name="mode" default="mock"/>

  <!-- init = startup joint position (the exact-model standing stance, stand_height 0.13):
       prevents the spawn collapse + first-command snap found in the 2E review. -->
  <xacro:macro name="barq_joint_if" params="name lower upper init">
    <joint name="${name}">
      <command_interface name="position">
        <param name="min">${lower}</param>
        <param name="max">${upper}</param>
      </command_interface>
      <state_interface name="position">
        <param name="initial_value">${init}</param>
      </state_interface>
      <state_interface name="velocity"/>
    </joint>
  </xacro:macro>

  <ros2_control name="barq_system" type="system">
    <hardware>
      <xacro:if value="${'$(arg mode)' == 'mock'}">
        <plugin>mock_components/GenericSystem</plugin>
      </xacro:if>
      <xacro:if value="${'$(arg mode)' == 'gazebo'}">
        <plugin>ign_ros2_control/IgnitionSystem</plugin>
      </xacro:if>
      <!-- mode=real (Stage 4) plugin slots in here -->
    </hardware>

    <xacro:barq_joint_if name="FL_hip_joint"   lower="-0.785" upper="0.785" init="0.0"/>
    <xacro:barq_joint_if name="FL_knee_joint"  lower="-1.57"  upper="1.57" init="1.047531"/>
    <xacro:barq_joint_if name="FL_ankle_joint" lower="-2.2"   upper="1.57" init="-1.928768"/>
    <xacro:barq_joint_if name="FR_hip_joint"   lower="-0.785" upper="0.785" init="0.0"/>
    <xacro:barq_joint_if name="FR_knee_joint"  lower="-1.57"  upper="1.57" init="1.047531"/>
    <xacro:barq_joint_if name="FR_ankle_joint" lower="-2.2"   upper="1.57" init="-1.928768"/>
    <xacro:barq_joint_if name="RL_hip_joint"   lower="-0.785" upper="0.785" init="0.0"/>
    <!-- Rear inits match the rear_raise=0.02 stance trim (depth 0.15, D-016) -->
    <xacro:barq_joint_if name="RL_knee_joint"  lower="-1.57"  upper="1.57" init="0.911998"/>
    <xacro:barq_joint_if name="RL_ankle_joint" lower="-2.2"   upper="1.57" init="-1.652637"/>
    <xacro:barq_joint_if name="RR_hip_joint"   lower="-0.785" upper="0.785" init="0.0"/>
    <xacro:barq_joint_if name="RR_knee_joint"  lower="-1.57"  upper="1.57" init="0.911998"/>
    <xacro:barq_joint_if name="RR_ankle_joint" lower="-2.2"   upper="1.57" init="-1.652637"/>
  </ros2_control>

  <!-- ═══════════════ Gazebo (Stage 2E, mode:=gazebo) ═══════════════ -->
  <xacro:if value="${'$(arg mode)' == 'gazebo'}">
    <gazebo>
      <plugin filename="ign_ros2_control-system" name="ign_ros2_control::IgnitionROS2ControlPlugin">
        <parameters>$(find barq_bringup)/config/ros2_controllers.yaml</parameters>
      </plugin>
    </gazebo>
    <gazebo reference="FL_tibia_link"><mu1>0.9</mu1><mu2>0.9</mu2></gazebo>
    <gazebo reference="FR_tibia_link"><mu1>0.9</mu1><mu2>0.9</mu2></gazebo>
    <gazebo reference="RL_tibia_link"><mu1>0.9</mu1><mu2>0.9</mu2></gazebo>
    <gazebo reference="RR_tibia_link"><mu1>0.9</mu1><mu2>0.9</mu2></gazebo>

    <!-- 2D lidar (STL-27L-class: 360 deg, 25 m, 21.6 kHz -> 2160 samples @ 10 Hz).
         frame/topic chosen for zero-config parity with the real driver (frame 'laser', /scan). -->
    <gazebo reference="laser">
      <sensor name="lidar2d" type="gpu_lidar">
        <topic>scan</topic>
        <update_rate>10</update_rate>
        <ignition_frame_id>laser</ignition_frame_id>
        <lidar>
          <scan>
            <horizontal>
              <samples>2160</samples>
              <resolution>1</resolution>
              <min_angle>-3.14159</min_angle>
              <max_angle>3.14159</max_angle>
            </horizontal>
          </scan>
          <range><min>0.15</min><max>25.0</max><resolution>0.01</resolution></range>
          <noise><type>gaussian</type><mean>0.0</mean><stddev>0.02</stddev></noise>
        </lidar>
        <always_on>1</always_on>
        <visualize>false</visualize>
      </sensor>
    </gazebo>

    <!-- IMU (BNO085-class noise) on the body. Topic name matches what the real Teensy/BNO085
         will publish at Stage 3 — the state estimator is hardware-parity by construction. -->
    <gazebo reference="base_link">
      <sensor name="imu" type="imu">
        <topic>imu</topic>
        <update_rate>100</update_rate>
        <ignition_frame_id>base_link</ignition_frame_id>
        <always_on>1</always_on>
        <imu>
          <angular_velocity>
            <x><noise type="gaussian"><mean>0</mean><stddev>0.002</stddev></noise></x>
            <y><noise type="gaussian"><mean>0</mean><stddev>0.002</stddev></noise></y>
            <z><noise type="gaussian"><mean>0</mean><stddev>0.002</stddev></noise></z>
          </angular_velocity>
          <linear_acceleration>
            <x><noise type="gaussian"><mean>0</mean><stddev>0.02</stddev></noise></x>
            <y><noise type="gaussian"><mean>0</mean><stddev>0.02</stddev></noise></y>
            <z><noise type="gaussian"><mean>0</mean><stddev>0.02</stddev></noise></z>
          </linear_acceleration>
        </imu>
      </sensor>
    </gazebo>

    <!-- Ground-truth odometry STOPGAP for SLAM (slam_toolbox needs odom->base_link TF; real
         legged odometry comes with the state estimator). Makes SLAM look artificially clean. -->
    <gazebo>
      <plugin filename="ignition-gazebo-odometry-publisher-system"
              name="ignition::gazebo::systems::OdometryPublisher">
        <odom_frame>odom</odom_frame>
        <robot_base_frame>base_link</robot_base_frame>
        <odom_publish_frequency>50</odom_publish_frequency>
        <dimensions>3</dimensions>
      </plugin>
    </gazebo>
  </xacro:if>

</robot>
